[2024-04-01T09:10:11.783+0000] {taskinstance.py:1157} INFO - Dependencies all met for dep_context=non-requeueable deps ti=<TaskInstance: deploy_project_kafkaClickhouse.task_Clickhouse_Consumer manual__2024-04-01T08:37:55.322732+00:00 [queued]>
[2024-04-01T09:10:11.789+0000] {taskinstance.py:1157} INFO - Dependencies all met for dep_context=requeueable deps ti=<TaskInstance: deploy_project_kafkaClickhouse.task_Clickhouse_Consumer manual__2024-04-01T08:37:55.322732+00:00 [queued]>
[2024-04-01T09:10:11.789+0000] {taskinstance.py:1359} INFO - Starting attempt 2 of 2
[2024-04-01T09:10:11.798+0000] {taskinstance.py:1380} INFO - Executing <Task(BashOperator): task_Clickhouse_Consumer> on 2024-04-01 08:37:55.322732+00:00
[2024-04-01T09:10:11.802+0000] {standard_task_runner.py:57} INFO - Started process 1805 to run task
[2024-04-01T09:10:11.804+0000] {standard_task_runner.py:84} INFO - Running: ['***', 'tasks', 'run', 'deploy_project_kafkaClickhouse', 'task_Clickhouse_Consumer', 'manual__2024-04-01T08:37:55.322732+00:00', '--job-id', '54', '--raw', '--subdir', 'DAGS_FOLDER/executeClickhouse.py', '--cfg-path', '/tmp/tmpyp4y5v3r']
[2024-04-01T09:10:11.805+0000] {standard_task_runner.py:85} INFO - Job 54: Subtask task_Clickhouse_Consumer
[2024-04-01T09:10:11.839+0000] {task_command.py:415} INFO - Running <TaskInstance: deploy_project_kafkaClickhouse.task_Clickhouse_Consumer manual__2024-04-01T08:37:55.322732+00:00 [running]> on host 977df1ccf323
[2024-04-01T09:10:11.889+0000] {taskinstance.py:1660} INFO - Exporting env vars: AIRFLOW_CTX_DAG_OWNER='***' AIRFLOW_CTX_DAG_ID='deploy_project_kafkaClickhouse' AIRFLOW_CTX_TASK_ID='task_Clickhouse_Consumer' AIRFLOW_CTX_EXECUTION_DATE='2024-04-01T08:37:55.322732+00:00' AIRFLOW_CTX_TRY_NUMBER='2' AIRFLOW_CTX_DAG_RUN_ID='manual__2024-04-01T08:37:55.322732+00:00'
[2024-04-01T09:10:11.890+0000] {subprocess.py:63} INFO - Tmp dir root location: /tmp
[2024-04-01T09:10:11.891+0000] {subprocess.py:75} INFO - Running command: ['/bin/bash', '-c', 'python /opt/***/dags/clickhouse/consumer.py']
[2024-04-01T09:10:11.900+0000] {subprocess.py:86} INFO - Output:
[2024-04-01T09:10:12.285+0000] {subprocess.py:93} INFO - Failed to connect to 172.18.0.1:9000
[2024-04-01T09:10:12.286+0000] {subprocess.py:93} INFO - Traceback (most recent call last):
[2024-04-01T09:10:12.286+0000] {subprocess.py:93} INFO -   File "/home/***/.local/lib/python3.8/site-packages/clickhouse_driver/connection.py", line 396, in connect
[2024-04-01T09:10:12.286+0000] {subprocess.py:93} INFO -     return self._init_connection(host, port)
[2024-04-01T09:10:12.286+0000] {subprocess.py:93} INFO -   File "/home/***/.local/lib/python3.8/site-packages/clickhouse_driver/connection.py", line 326, in _init_connection
[2024-04-01T09:10:12.286+0000] {subprocess.py:93} INFO -     self.socket = self._create_socket(host, port)
[2024-04-01T09:10:12.286+0000] {subprocess.py:93} INFO -   File "/home/***/.local/lib/python3.8/site-packages/clickhouse_driver/connection.py", line 297, in _create_socket
[2024-04-01T09:10:12.286+0000] {subprocess.py:93} INFO -     raise err
[2024-04-01T09:10:12.287+0000] {subprocess.py:93} INFO -   File "/home/***/.local/lib/python3.8/site-packages/clickhouse_driver/connection.py", line 288, in _create_socket
[2024-04-01T09:10:12.287+0000] {subprocess.py:93} INFO -     sock.connect(sa)
[2024-04-01T09:10:12.287+0000] {subprocess.py:93} INFO - ConnectionRefusedError: [Errno 111] Connection refused
[2024-04-01T09:10:12.287+0000] {subprocess.py:93} INFO - Consumer started
[2024-04-01T09:10:12.287+0000] {subprocess.py:93} INFO - Traceback (most recent call last):
[2024-04-01T09:10:12.287+0000] {subprocess.py:93} INFO -   File "/opt/***/dags/clickhouse/consumer.py", line 99, in <module>
[2024-04-01T09:10:12.287+0000] {subprocess.py:93} INFO -     main()
[2024-04-01T09:10:12.287+0000] {subprocess.py:93} INFO -   File "/opt/***/dags/clickhouse/consumer.py", line 46, in main
[2024-04-01T09:10:12.287+0000] {subprocess.py:93} INFO -     clickhouse_client.execute(CREATE_TABLE_QUERY)
[2024-04-01T09:10:12.287+0000] {subprocess.py:93} INFO -   File "/home/***/.local/lib/python3.8/site-packages/clickhouse_driver/client.py", line 370, in execute
[2024-04-01T09:10:12.287+0000] {subprocess.py:93} INFO -     with self.disconnect_on_error(query, settings):
[2024-04-01T09:10:12.288+0000] {subprocess.py:93} INFO -   File "/usr/local/lib/python3.8/contextlib.py", line 113, in __enter__
[2024-04-01T09:10:12.288+0000] {subprocess.py:93} INFO -     return next(self.gen)
[2024-04-01T09:10:12.288+0000] {subprocess.py:93} INFO -   File "/home/***/.local/lib/python3.8/site-packages/clickhouse_driver/client.py", line 314, in disconnect_on_error
[2024-04-01T09:10:12.288+0000] {subprocess.py:93} INFO -     self.establish_connection(settings)
[2024-04-01T09:10:12.288+0000] {subprocess.py:93} INFO -   File "/home/***/.local/lib/python3.8/site-packages/clickhouse_driver/client.py", line 301, in establish_connection
[2024-04-01T09:10:12.288+0000] {subprocess.py:93} INFO -     self.connection.force_connect()
[2024-04-01T09:10:12.288+0000] {subprocess.py:93} INFO -   File "/home/***/.local/lib/python3.8/site-packages/clickhouse_driver/connection.py", line 254, in force_connect
[2024-04-01T09:10:12.288+0000] {subprocess.py:93} INFO -     self.connect()
[2024-04-01T09:10:12.288+0000] {subprocess.py:93} INFO -   File "/home/***/.local/lib/python3.8/site-packages/clickhouse_driver/connection.py", line 417, in connect
[2024-04-01T09:10:12.288+0000] {subprocess.py:93} INFO -     raise err
[2024-04-01T09:10:12.288+0000] {subprocess.py:93} INFO - clickhouse_driver.errors.NetworkError: Code: 210. Connection refused (172.18.0.1:9000)
[2024-04-01T09:10:12.306+0000] {subprocess.py:97} INFO - Command exited with return code 1
[2024-04-01T09:10:12.316+0000] {taskinstance.py:1935} ERROR - Task failed with exception
Traceback (most recent call last):
  File "/home/airflow/.local/lib/python3.8/site-packages/airflow/operators/bash.py", line 210, in execute
    raise AirflowException(
airflow.exceptions.AirflowException: Bash command failed. The command returned a non-zero exit code 1.
[2024-04-01T09:10:12.319+0000] {taskinstance.py:1398} INFO - Marking task as FAILED. dag_id=deploy_project_kafkaClickhouse, task_id=task_Clickhouse_Consumer, execution_date=20240401T083755, start_date=20240401T091011, end_date=20240401T091012
[2024-04-01T09:10:12.327+0000] {standard_task_runner.py:104} ERROR - Failed to execute job 54 for task task_Clickhouse_Consumer (Bash command failed. The command returned a non-zero exit code 1.; 1805)
[2024-04-01T09:10:12.337+0000] {local_task_job_runner.py:228} INFO - Task exited with return code 1
[2024-04-01T09:10:12.349+0000] {taskinstance.py:2776} INFO - 0 downstream tasks scheduled from follow-on schedule check
