[2024-04-01T08:35:32.345+0000] {taskinstance.py:1157} INFO - Dependencies all met for dep_context=non-requeueable deps ti=<TaskInstance: deploy_project_kafkaClickhouse.task_Clickhouse_Consumer scheduled__2024-03-30T09:30:00+00:00 [queued]>
[2024-04-01T08:35:32.351+0000] {taskinstance.py:1157} INFO - Dependencies all met for dep_context=requeueable deps ti=<TaskInstance: deploy_project_kafkaClickhouse.task_Clickhouse_Consumer scheduled__2024-03-30T09:30:00+00:00 [queued]>
[2024-04-01T08:35:32.351+0000] {taskinstance.py:1359} INFO - Starting attempt 2 of 2
[2024-04-01T08:35:32.362+0000] {taskinstance.py:1380} INFO - Executing <Task(BashOperator): task_Clickhouse_Consumer> on 2024-03-30 09:30:00+00:00
[2024-04-01T08:35:32.366+0000] {standard_task_runner.py:57} INFO - Started process 1191 to run task
[2024-04-01T08:35:32.369+0000] {standard_task_runner.py:84} INFO - Running: ['***', 'tasks', 'run', 'deploy_project_kafkaClickhouse', 'task_Clickhouse_Consumer', 'scheduled__2024-03-30T09:30:00+00:00', '--job-id', '48', '--raw', '--subdir', 'DAGS_FOLDER/executeClickhouse.py', '--cfg-path', '/tmp/tmpe_3fmqg9']
[2024-04-01T08:35:32.370+0000] {standard_task_runner.py:85} INFO - Job 48: Subtask task_Clickhouse_Consumer
[2024-04-01T08:35:32.405+0000] {task_command.py:415} INFO - Running <TaskInstance: deploy_project_kafkaClickhouse.task_Clickhouse_Consumer scheduled__2024-03-30T09:30:00+00:00 [running]> on host 977df1ccf323
[2024-04-01T08:35:32.459+0000] {taskinstance.py:1660} INFO - Exporting env vars: AIRFLOW_CTX_DAG_OWNER='***' AIRFLOW_CTX_DAG_ID='deploy_project_kafkaClickhouse' AIRFLOW_CTX_TASK_ID='task_Clickhouse_Consumer' AIRFLOW_CTX_EXECUTION_DATE='2024-03-30T09:30:00+00:00' AIRFLOW_CTX_TRY_NUMBER='2' AIRFLOW_CTX_DAG_RUN_ID='scheduled__2024-03-30T09:30:00+00:00'
[2024-04-01T08:35:32.460+0000] {subprocess.py:63} INFO - Tmp dir root location: /tmp
[2024-04-01T08:35:32.460+0000] {subprocess.py:75} INFO - Running command: ['/bin/bash', '-c', 'python /opt/***/dags/clickhouse/consumer.py']
[2024-04-01T08:35:32.470+0000] {subprocess.py:86} INFO - Output:
[2024-04-01T08:38:38.880+0000] {local_task_job_runner.py:294} WARNING - State of this instance has been externally set to None. Terminating instance.
[2024-04-01T08:38:38.882+0000] {process_utils.py:131} INFO - Sending 15 to group 1191. PIDs of all processes in the group: [1192, 1191]
[2024-04-01T08:38:38.882+0000] {process_utils.py:86} INFO - Sending the signal 15 to group 1191
[2024-04-01T08:38:38.882+0000] {taskinstance.py:1630} ERROR - Received SIGTERM. Terminating subprocesses.
[2024-04-01T08:38:38.883+0000] {subprocess.py:104} INFO - Sending SIGTERM signal to process group
[2024-04-01T08:38:38.892+0000] {taskinstance.py:1935} ERROR - Task failed with exception
Traceback (most recent call last):
  File "/home/airflow/.local/lib/python3.8/site-packages/airflow/operators/bash.py", line 201, in execute
    result = self.subprocess_hook.run_command(
  File "/home/airflow/.local/lib/python3.8/site-packages/airflow/hooks/subprocess.py", line 91, in run_command
    for raw_line in iter(self.sub_process.stdout.readline, b""):
  File "/home/airflow/.local/lib/python3.8/site-packages/airflow/models/taskinstance.py", line 1632, in signal_handler
    raise AirflowException("Task received SIGTERM signal")
airflow.exceptions.AirflowException: Task received SIGTERM signal
[2024-04-01T08:38:38.896+0000] {taskinstance.py:1398} INFO - Marking task as FAILED. dag_id=deploy_project_kafkaClickhouse, task_id=task_Clickhouse_Consumer, execution_date=20240330T093000, start_date=20240401T083532, end_date=20240401T083838
[2024-04-01T08:38:38.908+0000] {standard_task_runner.py:104} ERROR - Failed to execute job 48 for task task_Clickhouse_Consumer ((psycopg2.errors.ForeignKeyViolation) insert or update on table "task_fail" violates foreign key constraint "task_fail_ti_fkey"
DETAIL:  Key (dag_id, task_id, run_id, map_index)=(deploy_project_kafkaClickhouse, task_Clickhouse_Consumer, scheduled__2024-03-30T09:30:00+00:00, -1) is not present in table "task_instance".

[SQL: INSERT INTO task_fail (task_id, dag_id, run_id, map_index, start_date, end_date, duration) VALUES (%(task_id)s, %(dag_id)s, %(run_id)s, %(map_index)s, %(start_date)s, %(end_date)s, %(duration)s) RETURNING task_fail.id]
[parameters: {'task_id': 'task_Clickhouse_Consumer', 'dag_id': 'deploy_project_kafkaClickhouse', 'run_id': 'scheduled__2024-03-30T09:30:00+00:00', 'map_index': -1, 'start_date': datetime.datetime(2024, 4, 1, 8, 35, 32, 345801, tzinfo=Timezone('UTC')), 'end_date': datetime.datetime(2024, 4, 1, 8, 38, 38, 895400, tzinfo=Timezone('UTC')), 'duration': 186}]
(Background on this error at: https://sqlalche.me/e/14/gkpj); 1191)
[2024-04-01T08:38:38.935+0000] {process_utils.py:79} INFO - Process psutil.Process(pid=1192, status='terminated', started='08:35:32') (1192) terminated with exit code None
[2024-04-01T08:38:38.935+0000] {process_utils.py:79} INFO - Process psutil.Process(pid=1191, status='terminated', exitcode=1, started='08:35:32') (1191) terminated with exit code 1
[2024-04-01T09:10:09.957+0000] {taskinstance.py:1157} INFO - Dependencies all met for dep_context=non-requeueable deps ti=<TaskInstance: deploy_project_kafkaClickhouse.task_Clickhouse_Consumer scheduled__2024-03-30T09:30:00+00:00 [queued]>
[2024-04-01T09:10:09.964+0000] {taskinstance.py:1157} INFO - Dependencies all met for dep_context=requeueable deps ti=<TaskInstance: deploy_project_kafkaClickhouse.task_Clickhouse_Consumer scheduled__2024-03-30T09:30:00+00:00 [queued]>
[2024-04-01T09:10:09.964+0000] {taskinstance.py:1359} INFO - Starting attempt 2 of 2
[2024-04-01T09:10:09.975+0000] {taskinstance.py:1380} INFO - Executing <Task(BashOperator): task_Clickhouse_Consumer> on 2024-03-30 09:30:00+00:00
[2024-04-01T09:10:09.980+0000] {standard_task_runner.py:57} INFO - Started process 1801 to run task
[2024-04-01T09:10:09.982+0000] {standard_task_runner.py:84} INFO - Running: ['***', 'tasks', 'run', 'deploy_project_kafkaClickhouse', 'task_Clickhouse_Consumer', 'scheduled__2024-03-30T09:30:00+00:00', '--job-id', '53', '--raw', '--subdir', 'DAGS_FOLDER/executeClickhouse.py', '--cfg-path', '/tmp/tmpz7c6wpvp']
[2024-04-01T09:10:09.983+0000] {standard_task_runner.py:85} INFO - Job 53: Subtask task_Clickhouse_Consumer
[2024-04-01T09:10:10.023+0000] {task_command.py:415} INFO - Running <TaskInstance: deploy_project_kafkaClickhouse.task_Clickhouse_Consumer scheduled__2024-03-30T09:30:00+00:00 [running]> on host 977df1ccf323
[2024-04-01T09:10:10.089+0000] {taskinstance.py:1660} INFO - Exporting env vars: AIRFLOW_CTX_DAG_OWNER='***' AIRFLOW_CTX_DAG_ID='deploy_project_kafkaClickhouse' AIRFLOW_CTX_TASK_ID='task_Clickhouse_Consumer' AIRFLOW_CTX_EXECUTION_DATE='2024-03-30T09:30:00+00:00' AIRFLOW_CTX_TRY_NUMBER='2' AIRFLOW_CTX_DAG_RUN_ID='scheduled__2024-03-30T09:30:00+00:00'
[2024-04-01T09:10:10.092+0000] {subprocess.py:63} INFO - Tmp dir root location: /tmp
[2024-04-01T09:10:10.092+0000] {subprocess.py:75} INFO - Running command: ['/bin/bash', '-c', 'python /opt/***/dags/clickhouse/consumer.py']
[2024-04-01T09:10:10.104+0000] {subprocess.py:86} INFO - Output:
[2024-04-01T09:10:10.501+0000] {subprocess.py:93} INFO - Failed to connect to 172.18.0.1:9000
[2024-04-01T09:10:10.501+0000] {subprocess.py:93} INFO - Traceback (most recent call last):
[2024-04-01T09:10:10.502+0000] {subprocess.py:93} INFO -   File "/home/***/.local/lib/python3.8/site-packages/clickhouse_driver/connection.py", line 396, in connect
[2024-04-01T09:10:10.502+0000] {subprocess.py:93} INFO -     return self._init_connection(host, port)
[2024-04-01T09:10:10.502+0000] {subprocess.py:93} INFO -   File "/home/***/.local/lib/python3.8/site-packages/clickhouse_driver/connection.py", line 326, in _init_connection
[2024-04-01T09:10:10.502+0000] {subprocess.py:93} INFO -     self.socket = self._create_socket(host, port)
[2024-04-01T09:10:10.502+0000] {subprocess.py:93} INFO -   File "/home/***/.local/lib/python3.8/site-packages/clickhouse_driver/connection.py", line 297, in _create_socket
[2024-04-01T09:10:10.502+0000] {subprocess.py:93} INFO -     raise err
[2024-04-01T09:10:10.502+0000] {subprocess.py:93} INFO -   File "/home/***/.local/lib/python3.8/site-packages/clickhouse_driver/connection.py", line 288, in _create_socket
[2024-04-01T09:10:10.502+0000] {subprocess.py:93} INFO -     sock.connect(sa)
[2024-04-01T09:10:10.502+0000] {subprocess.py:93} INFO - ConnectionRefusedError: [Errno 111] Connection refused
[2024-04-01T09:10:10.502+0000] {subprocess.py:93} INFO - Consumer started
[2024-04-01T09:10:10.503+0000] {subprocess.py:93} INFO - Traceback (most recent call last):
[2024-04-01T09:10:10.503+0000] {subprocess.py:93} INFO -   File "/opt/***/dags/clickhouse/consumer.py", line 99, in <module>
[2024-04-01T09:10:10.503+0000] {subprocess.py:93} INFO -     main()
[2024-04-01T09:10:10.503+0000] {subprocess.py:93} INFO -   File "/opt/***/dags/clickhouse/consumer.py", line 46, in main
[2024-04-01T09:10:10.503+0000] {subprocess.py:93} INFO -     clickhouse_client.execute(CREATE_TABLE_QUERY)
[2024-04-01T09:10:10.503+0000] {subprocess.py:93} INFO -   File "/home/***/.local/lib/python3.8/site-packages/clickhouse_driver/client.py", line 370, in execute
[2024-04-01T09:10:10.503+0000] {subprocess.py:93} INFO -     with self.disconnect_on_error(query, settings):
[2024-04-01T09:10:10.503+0000] {subprocess.py:93} INFO -   File "/usr/local/lib/python3.8/contextlib.py", line 113, in __enter__
[2024-04-01T09:10:10.503+0000] {subprocess.py:93} INFO -     return next(self.gen)
[2024-04-01T09:10:10.503+0000] {subprocess.py:93} INFO -   File "/home/***/.local/lib/python3.8/site-packages/clickhouse_driver/client.py", line 314, in disconnect_on_error
[2024-04-01T09:10:10.504+0000] {subprocess.py:93} INFO -     self.establish_connection(settings)
[2024-04-01T09:10:10.504+0000] {subprocess.py:93} INFO -   File "/home/***/.local/lib/python3.8/site-packages/clickhouse_driver/client.py", line 301, in establish_connection
[2024-04-01T09:10:10.504+0000] {subprocess.py:93} INFO -     self.connection.force_connect()
[2024-04-01T09:10:10.504+0000] {subprocess.py:93} INFO -   File "/home/***/.local/lib/python3.8/site-packages/clickhouse_driver/connection.py", line 254, in force_connect
[2024-04-01T09:10:10.504+0000] {subprocess.py:93} INFO -     self.connect()
[2024-04-01T09:10:10.504+0000] {subprocess.py:93} INFO -   File "/home/***/.local/lib/python3.8/site-packages/clickhouse_driver/connection.py", line 417, in connect
[2024-04-01T09:10:10.504+0000] {subprocess.py:93} INFO -     raise err
[2024-04-01T09:10:10.504+0000] {subprocess.py:93} INFO - clickhouse_driver.errors.NetworkError: Code: 210. Connection refused (172.18.0.1:9000)
[2024-04-01T09:10:10.521+0000] {subprocess.py:97} INFO - Command exited with return code 1
[2024-04-01T09:10:10.531+0000] {taskinstance.py:1935} ERROR - Task failed with exception
Traceback (most recent call last):
  File "/home/airflow/.local/lib/python3.8/site-packages/airflow/operators/bash.py", line 210, in execute
    raise AirflowException(
airflow.exceptions.AirflowException: Bash command failed. The command returned a non-zero exit code 1.
[2024-04-01T09:10:10.533+0000] {taskinstance.py:1398} INFO - Marking task as FAILED. dag_id=deploy_project_kafkaClickhouse, task_id=task_Clickhouse_Consumer, execution_date=20240330T093000, start_date=20240401T091009, end_date=20240401T091010
[2024-04-01T09:10:10.542+0000] {standard_task_runner.py:104} ERROR - Failed to execute job 53 for task task_Clickhouse_Consumer (Bash command failed. The command returned a non-zero exit code 1.; 1801)
[2024-04-01T09:10:10.557+0000] {local_task_job_runner.py:228} INFO - Task exited with return code 1
[2024-04-01T09:10:10.569+0000] {taskinstance.py:2776} INFO - 0 downstream tasks scheduled from follow-on schedule check
